Workbook
Name Slicer_Product_Name: #N/A
Name Slicer_Region: #N/A
Name Slicer_Unit_Price: #N/A

Sheet Project Instructions
A1: PR. Final Project - "Data Intelligence Dashboard"
A2: Dataset: Use the 'Final Project Dataset' sheet containing 200+ records of customer transactions.
A4: Objective:
A5: Create a full-fledged analysis and reporting solution using Excel to analyze customer transactions, find insights,
A6: and build visualizations and dashboards.
A8: Key Topics to Implement:
A9: - Date & Time Functions: TODAY, NOW, DATEDIF, EOMONTH
A10: - FILTER Function for multi-value returns
A11: - Conditional Formatting with Icons/Arrows
A12: - Create Timestamp (using NOW and iterative calculations)
A13: - WHAT-IF Analysis: Scenario Manager, Goal Seek
A14: - Linear Regression using Data Analysis Toolpak
... A30: - Use of all required formulas and functions as listed above

Sheet Dashboard

Sheet Final Project Dataset
A1: Transaction_ID | B1: Date | C1: Customer_ID | D1: Customer_Name | E1: Product_ID | F1: Product_Name | G1: Category | H1: Quantity | I1: Unit_Price | J1: Payment_Method | K1: Region | L1: Customer_Segment | M1: Customer_Since | N1: Total_Amount | O1: Product Frequency | P1: Most Frequency purches product | Q1: WHAT IF (SCENARIO MANAGER) | T1: DATE AND TIME FUNCTION | X1: First Later
A2: TRX0155 | B2: 45393 | C2: CUST023 | D2: Paul Baker | E2: P009 | F2: Monitor | G2: Electronics | H2: 3 | I2: 249.99 | J2: Cash | K2: Central | L2: Basic | M2: 44425 | N2: 749.97 | O2: =COUNTIF($F:$F,F2) -> 26 | P2: =INDEX(F:F,MATCH(MAX(O:O),O:O,0)) -> Bookshelf | Q2: QTY | R2: 200 | T2: TODAY | U2: =TODAY() -> 46078 | X2: =UPPER(LEFT(D2,1)&MID(D2,FIND(" ",D2)+1,1)) -> PB
A3: TRX0023 | B3: 45396 | C3: CUST013 | D3: Joseph Jackson | E3: P009 | F3: Monitor | G3: Electronics | H3: 3 | I3: 249.99 | J3: Credit Card | K3: Central | L3: Premium | M3: 44575 | N3: 749.97 | O3: =COUNTIF($F:$F,F3) -> 26 | Q3: PRICE | R3: 500 | T3: NOW | U3: =NOW() -> 46078.606 | X3: =UPPER(LEFT(D3,1)&MID(D3,FIND(" ",D3)+1,1)) -> JJ
A4: TRX0139 | B4: 45399 | C4: CUST021 | D4: Kevin Scott | E4: P005 | F4: Blender | G4: Appliances | H4: 3 | I4: 59.99 | J4: PayPal | K4: South | L4: Standard | M4: 45262 | N4: 179.97 | O4: =COUNTIF($F:$F,F4) -> 29 | Q4: TOTAL AMOUNT | R4: =R2*R3 -> 100000 | T4: EOMONTH | U4: =EOMONTH(U3,5) -> 46234 | X4: =UPPER(LEFT(D4,1)&MID(D4,FIND(" ",D4)+1,1)) -> KS
A5: TRX0043 | B5: 45400 | C5: CUST046 | D5: Kathleen Bennett | E5: P005 | F5: Blender | G5: Appliances | H5: 3 | I5: 59.99 | J5: Cash | K5: North | L5: Premium | M5: 45114 | N5: 179.97 | O5: =COUNTIF($F:$F,F5) -> 29 | X5: =UPPER(LEFT(D5,1)&MID(D5,FIND(" ",D5)+1,1)) -> KB
A6: TRX0212 | B6: 45400 | C6: CUST003 | D6: Michael Brown | E6: P008 | F6: Bookshelf | G6: Furniture | H6: 5 | I6: 149.99 | J6: Credit Card | K6: North | L6: Premium | M6: 45295 | N6: 749.95 | O6: =COUNTIF($F:$F,F6) -> 35 | Q6: WHAT IF (GOAL SEEK) | X6: =UPPER(LEFT(D6,1)&MID(D6,FIND(" ",D6)+1,1)) -> MB
A7: TRX0092 | B7: 45403 | C7: CUST024 | D7: Dorothy Nelson | E7: P005 | F7: Blender | G7: Appliances | H7: 2 | I7: 59.99 | J7: Cash | K7: West | L7: Standard | M7: 44746 | N7: 119.98 | O7: =COUNTIF($F:$F,F7) -> 29 | Q7: QTY | R7: 200 | X7: =UPPER(LEFT(D7,1)&MID(D7,FIND(" ",D7)+1,1)) -> DN
A8: TRX0193 | B8: 45403 | C8: CUST024 | D8: Dorothy Nelson | E8: P003 | F8: Headphones | G8: Electronics | H8: 5 | I8: 149.99 | J8: Credit Card | K8: Central | L8: Standard | M8: 44418 | N8: 749.95 | O8: =COUNTIF($F:$F,F8) -> 16 | Q8: PRICE | R8: 500 | T8: TIME STEMP | V8: Total Quantity | W8: Total Unit Price | X8: =UPPER(LEFT(D8,1)&MID(D8,FIND(" ",D8)+1,1)) -> DN
A9: TRX0240 | B9: 45403 | C9: CUST017 | D9: Charles Allen | E9: P005 | F9: Blender | G9: Appliances | H9: 3 | I9: 59.99 | J9: Debit Card | K9: South | L9: Basic | M9: 45007 | N9: 179.97 | O9: =COUNTIF($F:$F,F9) -> 29 | Q9: TOTAL AMOUNT | R9: =R7*R8 -> 100000 | T9: =NOW() -> 46078.606 | V9: =SUM(H2:H251) -> 753 | W9: =SUM(I2:I251) -> 74167.5 | X9: =UPPER(LEFT(D9,1)&MID(D9,FIND(" ",D9)+1,1)) -> CA
A10: TRX0135 | B10: 45405 | C10: CUST009 | D10: Robert Thomas | E10: P001 | F10: Laptop | G10: Electronics | H10: 3 | I10: 899.99 | J10: PayPal | K10: East | L10: Standard | M10: 45299 | N10: 2699.97 | O10: =COUNTIF($F:$F,F10) -> 24 | X10: =UPPER(LEFT(D10,1)&MID(D10,FIND(" ",D10)+1,1)) -> RT
A11: TRX0185 | B11: 45408 | C11: CUST026 | D11: Karen Hill | E11: P005 | F11: Blender | G11: Appliances | H11: 3 | I11: 59.99 | J11: Cash | K11: West | L11: Premium | M11: 45207 | N11: 179.97 | O11: =COUNTIF($F:$F,F11) -> 29 | X11: =UPPER(LEFT(D11,1)&MID(D11,FIND(" ",D11)+1,1)) -> KH
A12: TRX0138 | B12: 45408 | C12: CUST022 | D12: Susan Green | E12: P008 | F12: Bookshelf | G12: Furniture | H12: 1 | I12: 149.99 | J12: Credit Card | K12: West | L12: Standard | M12: 45103 | N12: 149.99 | O12: =COUNTIF($F:$F,F12) -> 35 | R12: Total Amount | X12: =UPPER(LEFT(D12,1)&MID(D12,FIND(" ",D12)+1,1)) -> SG
A13: TRX0209 | B13: 45408 | C13: CUST046 | D13: Kathleen Bennett | E13: P008 | F13: Bookshelf | G13: Furniture | H13: 5 | I13: 149.99 | J13: Debit Card | K13: North | L13: Basic | M13: 44830 | N13: 749.95 | O13: =COUNTIF($F:$F,F13) -> 35 | R13: =SUM(N2:N251) -> 229192.47 | X13: =UPPER(LEFT(D13,1)&MID(D13,FIND(" ",D13)+1,1)) -> KB
A14: TRX0246 | B14: 45408 | C14: CUST041 | D14: Peter Richardson | E14: P008 | F14: Bookshelf | G14: Furniture | H14: 3 | I14: 149.99 | J14: Cash | K14: North | L14: Premium | M14: 44806 | N14: 449.97 | O14: =COUNTIF($F:$F,F14) -> 35 | X14: =UPPER(LEFT(D14,1)&MID(D14,FIND(" ",D14)+1,1)) -> PR
A15: TRX0067 | B15: 45409 | C15: CUST043 | D15: Dennis Gray | E15: P005 | F15: Blender | G15: Appliances | H15: 3 | I15: 59.99 | J15: Credit Card | K15: North | L15: Standard | M15: 45351 | N15: 179.97 | O15: =COUNTIF($F:$F,F15) -> 29 | X15: =UPPER(LEFT(D15,1)&MID(D15,FIND(" ",D15)+1,1)) -> DG
A16: TRX0191 | B16: 45409 | C16: CUST038 | D16: Michelle Rogers | E16: P002 | F16: Smartphone | G16: Electronics | H16: 3 | I16: 699.99 | J16: Credit Card | K16: West | L16: Basic | M16: 44577 | N16: 2099.97 | O16: =COUNTIF($F:$F,F16) -> 31 | X16: =UPPER(LEFT(D16,1)&MID(D16,FIND(" ",D16)+1,1)) -> MR
A17: TRX0230 | B17: 45409 | C17: CUST027 | D17: George Adams | E17: P001 | F17: Laptop | G17: Electronics | H17: 1 | I17: 899.99 | J17: Debit Card | K17: North | L17: Standard | M17: 44920 | N17: 899.99 | O17: =COUNTIF($F:$F,F17) -> 24 | X17: =UPPER(LEFT(D17,1)&MID(D17,FIND(" ",D17)+1,1)) -> GA
A18: TRX0049 | B18: 45410 | C18: CUST025 | D18: Mark Carter | E18: P008 | F18: Bookshelf | G18: Furniture | H18: 4 | I18: 149.99 | J18: Debit Card | K18: North | L18: Premium | M18: 45374 | N18: 599.96 | O18: =COUNTIF($F:$F,F18) -> 35 | X18: =UPPER(LEFT(D18,1)&MID(D18,FIND(" ",D18)+1,1)) -> MC
A19: TRX0134 | B19: 45410 | C19: CUST010 | D19: Maria Garcia | E19: P002 | F19: Smartphone | G19: Electronics | H19: 2 | I19: 699.99 | J19: Cash | K19: North | L19: Basic | M19: 44781 | N19: 1399.98 | O19: =COUNTIF($F:$F,F19) -> 31 | Q19: List 1 | R19: List 2 | S19: Final List | X19: =UPPER(LEFT(D19,1)&MID(D19,FIND(" ",D19)+1,1)) -> MG
A20: TRX0122 | B20: 45410 | C20: CUST025 | D20: Mark Carter | E20: P001 | F20: Laptop | G20: Electronics | H20: 4 | I20: 899.99 | J20: Credit Card | K20: West | L20: Standard | M20: 45327 | N20: 3599.96 | O20: =COUNTIF($F:$F,F20) -> 24 | Q20: Lisa Anderson | R20: Michael Brown | S20: =IF(COUNTIF(Q20:Q36,R20)>0,R20,"-") -> - | X20: =UPPER(LEFT(D20,1)&MID(D20,FIND(" ",D20)+1,1)) -> MC
A21: TRX0222 | B21: 45410 | C21: CUST048 | D21: Virginia Sanders | E21: P009 | F21: Monitor | G21: Electronics | H21: 3 | I21: 249.99 | J21: Credit Card | K21: North | L21: Premium | M21: 45224 | N21: 749.97 | O21: =COUNTIF($F:$F,F21) -> 26 | Q21: Patricia Moore | R21: Dorothy Nelson | S21: =IF(COUNTIF(Q21:Q37,R21)>0,R21,"-") -> - | X21: =UPPER(LEFT(D21,1)&MID(D21,FIND(" ",D21)+1,1)) -> VS
A22: TRX0231 | B22: 45412 | C22: CUST018 | D22: Barbara Young | E22: P002 | F22: Smartphone | G22: Electronics | H22: 5 | I22: 699.99 | J22: Cash | K22: West | L22: Basic | M22: 45167 | N22: 3499.95 | O22: =COUNTIF($F:$F,F22) -> 31 | Q22: Paul Baker | R22: Dorothy Nelson | S22: =IF(COUNTIF(Q22:Q38,R22)>0,R22,"-") -> - | X22: =UPPER(LEFT(D22,1)&MID(D22,FIND(" ",D22)+1,1)) -> BY
A23: TRX0239 | B23: 45413 | C23: CUST012 | D23: Patricia Moore | E23: P002 | F23: Smartphone | G23: Electronics | H23: 4 | I23: 699.99 | J23: Cash | K23: East | L23: Standard | M23: 44409 | N23: 2799.96 | O23: =COUNTIF($F:$F,F23) -> 31 | Q23: Edward Mitchell | R23: Charles Allen | S23: =IF(COUNTIF(Q23:Q39,R23)>0,R23,"-") -> Charles Allen | X23: =UPPER(LEFT(D23,1)&MID(D23,FIND(" ",D23)+1,1)) -> PM
A24: TRX0204 | B24: 45415 | C24: CUST044 | D24: Cynthia Price | E24: P009 | F24: Monitor | G24: Electronics | H24: 4 | I24: 249.99 | J24: PayPal | K24: North | L24: Standard | M24: 44468 | N24: 999.96 | O24: =COUNTIF($F:$F,F24) -> 26 | Q24: Betty Campbell | R24: Robert Thomas | S24: =IF(COUNTIF(Q24:Q40,R24)>0,R24,"-") -> Robert Thomas | X24: =UPPER(LEFT(D24,1)&MID(D24,FIND(" ",D24)+1,1)) -> CP
A25: TRX0242 | B25: 45416 | C25: CUST025 | D25: Mark Carter | E25: P007 | F25: Desk | G25: Furniture | H25: 4 | I25: 299.99 | J25: Cash | K25: West | L25: Premium | M25: 44716 | N25: 1199.96 | O25: =COUNTIF($F:$F,F25) -> 26 | Q25: Jennifer Taylor | R25: Karen Hill | S25: =IF(COUNTIF(Q25:Q41,R25)>0,R25,"-") -> - | X25: =UPPER(LEFT(D25,1)&MID(D25,FIND(" ",D25)+1,1)) -> MC
A26: TRX0071 | B26: 45422 | C26: CUST036 | D26: Nancy Collins | E26: P009 | F26: Monitor | G26: Electronics | H26: 5 | I26: 249.99 | J26: Credit Card | K26: West | L26: Standard | M26: 44525 | N26: 1249.95 | O26: =COUNTIF($F:$F,F26) -> 26 | Q26: Raymond Ross | R26: Susan Green | S26: =IF(COUNTIF(Q26:Q42,R26)>0,R26,"-") -> Susan Green | X26: =UPPER(LEFT(D26,1)&MID(D26,FIND(" ",D26)+1,1)) -> NC
A27: TRX0040 | B27: 45424 | C27: CUST022 | D27: Susan Green | E27: P007 | F27: Desk | G27: Furniture | H27: 5 | I27: 299.99 | J27: PayPal | K27: East | L27: Basic | M27: 45168 | N27: 1499.95 | O27: =COUNTIF($F:$F,F27) -> 26 | Q27: Kevin Scott | R27: Kathleen Bennett | S27: =IF(COUNTIF(Q27:Q43,R27)>0,R27,"-") -> Kathleen Bennett | X27: =UPPER(LEFT(D27,1)&MID(D27,FIND(" ",D27)+1,1)) -> SG
A28: TRX0235 | B28: 45424 | C28: CUST014 | D28: Linda Martin | E28: P004 | F28: Coffee Maker | G28: Appliances | H28: 3 | I28: 79.99 | J28: PayPal | K28: East | L28: Premium | M28: 45012 | N28: 239.97 | O28: =COUNTIF($F:$F,F28) -> 14 | Q28: Robert Thomas | R28: Peter Richardson | S28: =IF(COUNTIF(Q28:Q44,R28)>0,R28,"-") -> - | X28: =UPPER(LEFT(D28,1)&MID(D28,FIND(" ",D28)+1,1)) -> LM
A29: TRX0004 | B29: 45424 | C29: CUST012 | D29: Patricia Moore | E29: P010 | F29: Keyboard | G29: Electronics | H29: 5 | I29: 89.99 | J29: Cash | K29: North | L29: Premium | M29: 44919 | N29: 449.95 | O29: =COUNTIF($F:$F,F29) -> 34 | Q29: Kathleen Bennett | R29: Dennis Gray | S29: =IF(COUNTIF(Q29:Q45,R29)>0,R29,"-") -> - | X29: =UPPER(LEFT(D29,1)&MID(D29,FIND(" ",D29)+1,1)) -> PM
A30: TRX0063 | B30: 45425 | C30: CUST030 | D30: Helen Roberts | E30: P005 | F30: Blender | G30: Appliances | H30: 2 | I30: 59.99 | J30: Debit Card | K30: Central | L30: Standard | M30: 45214 | N30: 119.98 | O30: =COUNTIF($F:$F,F30) -> 29 | Q30: Patricia Moore | R30: Michelle Rogers | S30: =IF(COUNTIF(Q30:Q46,R30)>0,R30,"-") -> - | X30: =UPPER(LEFT(D30,1)&MID(D30,FIND(" ",D30)+1,1)) -> HR
A31: TRX0241 | B31: 45427 | C31: CUST029 | D31: Edwa+D31:E72rd Mitchell | E31: P005 | F31: Blender | G31: Appliances | H31: 4 | I31: 59.99 | J31: Debit Card | K31: East | L31: Standard | M31: 44867 | N31: 239.96 | O31: =COUNTIF($F:$F,F31) -> 29 | Q31: Helen Roberts | R31: George Adams | S31: =IF(COUNTIF(Q31:Q47,R31)>0,R31,"-") -> - | X31: =UPPER(LEFT(D31,1)&MID(D31,FIND(" ",D31)+1,1)) -> EM
... A36: TRX0232 | B36: 45434 | C36: CUST012 | D36: Patricia Moore | E36: P007 | F36: Desk | G36: Furniture | H36: 3 | I36: 299.99 | J36: Credit Card | K36: East | L36: Basic | M36: 44824 | N36: 899.97 | O36: =COUNTIF($F:$F,F36) -> 26 | Q36: Margaret Wright | R36: Barbara Young | S36: =IF(COUNTIF(Q36:Q52,R36)>0,R36,"-") -> - | X36: =UPPER(LEFT(D36,1)&MID(D36,FIND(" ",D36)+1,1)) -> PM
A37: TRX0021 | B37: 45435 | C37: CUST006 | D37: Lisa Anderson | E37: P004 | F37: Coffee Maker | G37: Appliances | H37: 3 | I37: 79.99 | J37: Cash | K37: South | L37: Basic | M37: 45046 | N37: 239.97 | O37: =COUNTIF($F:$F,F37) -> 14 | X37: =UPPER(LEFT(D37,1)&MID(D37,FIND(" ",D37)+1,1)) -> LA
A38: TRX0245 | B38: 45438 | C38: CUST031 | D38: Steven Turner | E38: P006 | F38: Office Chair | G38: Furniture | H38: 3 | I38: 199.99 | J38: Credit Card | K38: North | L38: Premium | M38: 45292 | N38: 599.97 | O38: =COUNTIF($F:$F,F38) -> 15 | X38: =UPPER(LEFT(D38,1)&MID(D38,FIND(" ",D38)+1,1)) -> ST
A39: TRX0015 | B39: 45440 | C39: CUST008 | D39: Jennifer Taylor | E39: P002 | F39: Smartphone | G39: Electronics | H39: 5 | I39: 699.99 | J39: PayPal | K39: West | L39: Standard | M39: 44407 | N39: 3499.95 | O39: =COUNTIF($F:$F,F39) -> 31 | X39: =UPPER(LEFT(D39,1)&MID(D39,FIND(" ",D39)+1,1)) -> JT
A40: TRX0202 | B40: 45441 | C40: CUST035 | D40: Harry Morgan | E40: P010 | F40: Keyboard | G40: Electronics | H40: 3 | I40: 89.99 | J40: PayPal | K40: Central | L40: Premium | M40: 45120 | N40: 269.97 | O40: =COUNTIF($F:$F,F40) -> 34 | X40: =UPPER(LEFT(D40,1)&MID(D40,FIND(" ",D40)+1,1)) -> HM
A41: TRX0042 | B41: 45443 | C41: CUST019 | D41: Daniel King | E41: P004 | F41: Coffee Maker | G41: Appliances | H41: 1 | I41: 79.99 | J41: Cash | K41: North | L41: Standard | M41: 44917 | N41: 79.99 | O41: =COUNTIF($F:$F,F41) -> 14 | X41: =UPPER(LEFT(D41,1)&MID(D41,FIND(" ",D41)+1,1)) -> DK
A42: TRX0128 | B42: 45444 | C42: CUST040 | D42: Sharon Butler | E42: P005 | F42: Blender | G42: Appliances | H42: 2 | I42: 59.99 | J42: Cash | K42: West | L42: Basic | M42: 45390 | N42: 119.98 | O42: =COUNTIF($F:$F,F42) -> 29 | X42: =UPPER(LEFT(D42,1)&MID(D42,FIND(" ",D42)+1,1)) -> SB
A43: TRX0117 | B43: 45444 | C43: CUST017 | D43: Charles Allen | E43: P010 | F43: Keyboard | G43: Electronics | H43: 1 | I43: 89.99 | J43: Cash | K43: North | L43: Basic | M43: 45141 | N43: 89.99 | O43: =COUNTIF($F:$F,F43) -> 34 | X43: =UPPER(LEFT(D43,1)&MID(D43,FIND(" ",D43)+1,1)) -> CA
A44: TRX0208 | B44: 45446 | C44: CUST004 | D44: Sarah Davis | E44: P010 | F44: Keyboard | G44: Electronics | H44: 5 | I44: 89.99 | J44: Credit Card | K44: East | L44: Standard | M44: 44587 | N44: 449.95 | O44: =COUNTIF($F:$F,F44) -> 34 | X44: =UPPER(LEFT(D44,1)&MID(D44,FIND(" ",D44)+1,1)) -> SD
...

Sheet pivot table
F3: Row Labels | G3: Product_Name | H3: Sum of Quantity | I3: Sum of Total_Amount | P3: Row Labels | Q3: Sum of Unit_Price | S3: Row Labels | T3: Sum of Quantity | V3: Row Labels | W3: Sum of Unit_Price | Y3: Row Labels | Z3: Sum of Unit_Price | AD3: Row Labels | AE3: Sum of Unit_Price
F4: Appliances | G4: Blender | H4: 87 | I4: 5219.13 | P4: 2024 | Q4: 52088.22 | S4: 2024 | T4: 527 | V4: Central | W4: 14219.46 | Y4: Blender | Z4: 1739.71 | AD4: Central | AE4: 14219.46
G5: Coffee Maker | H5: 39 | I5: 3119.61 | P5: 2025 | Q5: 22079.28 | S5: 2025 | T5: 226 | V5: East | W5: 16569.52 | Y5: Bookshelf | Z5: 5249.65 | AD5: East | AE5: 16569.52
F6: Electronics | G6: Headphones | H6: 47 | I6: 7049.53 | P6: Grand Total | Q6: 74167.5 | S6: Grand Total | T6: 753 | V6: North | W6: 19749.41 | Y6: Coffee Maker | Z6: 1119.86 | AD6: 45405 | AE6: 899.99
G7: Keyboard | H7: 89 | I7: 8009.11 | V7: South | W7: 10189.58 | Y7: Desk | Z7: 7799.74 | AD7: 45413 | AE7: 699.99
G8: Laptop | H8: 75 | I8: 67499.25 | V8: West | W8: 13439.53 | Y8: Headphones | Z8: 2399.84 | AD8: 45424 | AE8: 379.98
G9: Monitor | H9: 88 | I9: 21999.12 | V9: Grand Total | W9: 74167.5 | Y9: Keyboard | Z9: 3059.66 | AD9: 45427 | AE9: 59.99
G10: Smartphone | H10: 96 | I10: 67199.04 | Y10: Laptop | Z10: 21599.76 | AD10: 45434 | AE10: 299.99
F11: Furniture | G11: Bookshelf | H11: 102 | I11: 15298.98 | Y11: Monitor | Z11: 6499.74 | AD11: 45446 | AE11: 89.99
G12: Desk | H12: 78 | I12: 23399.22 | Y12: Office Chair | Z12: 2999.85 | AD12: 45449 | AE12: 249.99
G13: Office Chair | H13: 52 | I13: 10399.48 | Y13: Smartphone | Z13: 21699.69 | AD13: 45450 | AE13: 149.99
F14: Grand Total | H14: 753 | I14: 229192.47 | Y14: Grand Total | Z14: 74167.5 | AD14: 45452 | AE14: 59.99
AD15: 45459 | AE15: 899.99
AD16: 45460 | AE16: 299.99
AD17: 45471 | AE17: 1599.98
AD18: 45472 | AE18: 149.99
AD19: 45481 | AE19: 699.99
AD20: 45510 | AE20: 149.99
AD21: 45517 | AE21: 249.99
AD22: 45522 | AE22: 89.99
AD23: 45523 | AE23: 1049.98
AD24: 45544 | AE24: 59.99
AD25: 45551 | AE25: 199.99
AD26: 45554 | AE26: 239.98
... AD47: 45758 | AE47: 89.99
AD48: North | AE48: 19749.41
AD49: South | AE49: 10189.58
AD50: West | AE50: 13439.53
AD51: Grand Total | AE51: 74167.5

Sheet High value customer
A1: Name | B1: Total sales | C1: High Value Customer
A2: Paul Baker | B2: =SUMIFS('Final Project Dataset'!$N:$N,'Final Project Dataset'!$D:$D,A2) -> 8309.74 | C2: =IF(B2>=10000,"High value","Normal") -> Normal
A3: Joseph Jackson | B3: =SUMIFS('Final Project Dataset'!$N:$N,'Final Project Dataset'!$D:$D,A3) -> 6949.84 | C3: =IF(B3>=10000,"High value","Normal") -> Normal
A4: Kevin Scott | B4: =SUMIFS('Final Project Dataset'!$N:$N,'Final Project Dataset'!$D:$D,A4) -> 3259.87 | C4: =IF(B4>=10000,"High value","Normal") -> Normal
A5: Kathleen Bennett | B5: =SUMIFS('Final Project Dataset'!$N:$N,'Final Project Dataset'!$D:$D,A5) -> 4309.81 | C5: =IF(B5>=10000,"High value","Normal") -> Normal
A6: Michael Brown | B6: =SUMIFS('Final Project Dataset'!$N:$N,'Final Project Dataset'!$D:$D,A6) -> 6169.74 | C6: =IF(B6>=10000,"High value","Normal") -> Normal
A7: Dorothy Nelson | B7: =SUMIFS('Final Project Dataset'!$N:$N,'Final Project Dataset'!$D:$D,A7) -> 8269.79 | C7: =IF(B7>=10000,"High value","Normal") -> Normal
A8: Charles Allen | B8: =SUMIFS('Final Project Dataset'!$N:$N,'Final Project Dataset'!$D:$D,A8) -> 5089.73 | C8: =IF(B8>=10000,"High value","Normal") -> Normal
A9: Robert Thomas | B9: =SUMIFS('Final Project Dataset'!$N:$N,'Final Project Dataset'!$D:$D,A9) -> 3509.9 | C9: =IF(B9>=10000,"High value","Normal") -> Normal
A10: Karen Hill | B10: =SUMIFS('Final Project Dataset'!$N:$N,'Final Project Dataset'!$D:$D,A10) -> 8009.77 | C10: =IF(B10>=10000,"High value","Normal") -> Normal
A11: Susan Green | B11: =SUMIFS('Final Project Dataset'!$N:$N,'Final Project Dataset'!$D:$D,A11) -> 1979.89 | C11: =IF(B11>=10000,"High value","Normal") -> Normal
A12: Peter Richardson | B12: =SUMIFS('Final Project Dataset'!$N:$N,'Final Project Dataset'!$D:$D,A12) -> 5949.85 | C12: =IF(B12>=10000,"High value","Normal") -> Normal
A13: Dennis Gray | B13: =SUMIFS('Final Project Dataset'!$N:$N,'Final Project Dataset'!$D:$D,A13) -> 479.92 | C13: =IF(B13>=10000,"High value","Normal") -> Normal
... A52: John Smith | B52: =SUMIFS('Final Project Dataset'!$N:$N,'Final Project Dataset'!$D:$D,A52) -> 599.96 | C52: =IF(B52>=10000,"High value","Normal") -> Normal

Sheet LINIER REGRETIONS
A1: INEAR REGRETIONS
A2: SUMMARY OUTPUT
A4: Regression Statistics
A5: Multiple R | B5: 0.45808036
A6: R Square | B6: 0.20983762
A7: Adjusted R Square | B7: 0.20665148
A8: Standard Error | B8: 1.1906792
A9: Observations | B9: 250
A11: ANOVA
B12: df | C12: SS | D12: MS | E12: F | F12: Significance F
A13: Regression | B13: 1 | C13: 93.370185 | D13: 93.370185 | E13: 65.859537 | F13: 2.2586479e-14
A14: Residual | B14: 248 | C14: 351.59381 | D14: 1.417717
A15: Total | B15: 249 | C15: 444.964
B17: Coefficients | C17: Standard Error | D17: t Stat | E17: P-value | F17: Lower 95% | G17: Upper 95% | H17: Lower 95.0% | I17: Upper 95.0%
A18: Intercept | B18: 2.468256 | C18: 0.10079723 | D18: 24.487341 | E18: 3.9188263e-68 | F18: 2.2697283 | G18: 2.6667838 | H18: 2.2697283 | I18: 2.6667838
A19: X Variable 1 | B19: 0.00059310844 | C19: 7.3084414e-05 | D19: 8.1153889 | E19: 2.2586479e-14 | F19: 0.00044916316 | G19: 0.00073705372 | H19: 0.00044916316 | I19: 0.00073705372
